# Translation of Odoo Server.
# This file contains the translation of the following modules:
# 	* account_online_sync_ar
#
msgid ""
msgstr ""
"Project-Id-Version: Odoo Server 13.0+e\n"
"Report-Msgid-Bugs-To: \n"
"POT-Creation-Date: 2021-07-27 19:29+0000\n"
"PO-Revision-Date: 2021-07-27 19:29+0000\n"
"Last-Translator: \n"
"Language-Team: \n"
"MIME-Version: 1.0\n"
"Content-Type: text/plain; charset=UTF-8\n"
"Content-Transfer-Encoding: \n"
"Plural-Forms: \n"

#. module: account_online_sync_ar
#: code:addons/account_online_sync_ar/models/account_online_provider.py:0
#, python-format
msgid ""
"100: Register - The API registers a new process (through a REST request)"
msgstr ""

#. module: account_online_sync_ar
#: code:addons/account_online_sync_ar/models/account_online_provider.py:0
#, python-format
msgid ""
"101: Starting - The process information was obtained to start operating"
msgstr ""

#. module: account_online_sync_ar
#: code:addons/account_online_sync_ar/models/account_online_provider.py:0
#, python-format
msgid "102: Running - The process is running (login successful)"
msgstr ""

#. module: account_online_sync_ar
#: code:addons/account_online_sync_ar/models/account_online_provider.py:0
#, python-format
msgid "103: TokenReceived - The process received the token"
msgstr ""

#. module: account_online_sync_ar
#: code:addons/account_online_sync_ar/models/account_online_provider.py:0
#, python-format
msgid ""
"200: Finish - The connection has been successful. Data has been extracted"
msgstr ""

#. module: account_online_sync_ar
#: code:addons/account_online_sync_ar/models/account_online_provider.py:0
#, python-format
msgid ""
"201: Pending - The connection has been successful. We have partially "
"extracted information but data will still be extracted in background "
"processes."
msgstr ""

#. module: account_online_sync_ar
#: code:addons/account_online_sync_ar/models/account_online_provider.py:0
#, python-format
msgid ""
"202: NoTransactions - The connection has been successful. However, no "
"transactions were found."
msgstr ""

#. module: account_online_sync_ar
#: code:addons/account_online_sync_ar/models/account_online_provider.py:0
#, python-format
msgid ""
"203: PartialTransactions - The connection has been successful. However, more"
" than one account does not have transactions."
msgstr ""

#. module: account_online_sync_ar
#: code:addons/account_online_sync_ar/models/account_online_provider.py:0
#, python-format
msgid ""
"204: Incomplete - The connection has been successful. However, the data "
"downloaded is incompleted."
msgstr ""

#. module: account_online_sync_ar
#: code:addons/account_online_sync_ar/models/account_online_provider.py:0
#, python-format
msgid ""
"206: NoAccounts - The connection has been successful. However, there were no"
" accounts linked to the given credentials."
msgstr ""

#. module: account_online_sync_ar
#: code:addons/account_online_sync_ar/models/account_online_provider.py:0
#, python-format
msgid "400: Bad Request."
msgstr ""

#. module: account_online_sync_ar
#: code:addons/account_online_sync_ar/models/account_online_provider.py:0
#, python-format
msgid ""
"401: Unauthorized - The value of one of the given Authentication Fields was "
"not accepted by the institution. Please verify the information and try "
"again."
msgstr ""

#. module: account_online_sync_ar
#: code:addons/account_online_sync_ar/models/account_online_provider.py:0
#, python-format
msgid "402: Payment Required"
msgstr ""

#. module: account_online_sync_ar
#: code:addons/account_online_sync_ar/models/account_online_provider.py:0
#, python-format
msgid ""
"403: Forbidden or Invalidtoken - The given token value introduced was not "
"accepted by the institution or the expiration time was reached."
msgstr ""

#. module: account_online_sync_ar
#: code:addons/account_online_sync_ar/models/account_online_provider.py:0
#, python-format
msgid "404: Not Found."
msgstr ""

#. module: account_online_sync_ar
#: code:addons/account_online_sync_ar/models/account_online_provider.py:0
#, python-format
msgid ""
"405: Locked - The institution has blocked the given credential, please "
"contact your institution and make sure your connection to the site is "
"working properly before trying again."
msgstr ""

#. module: account_online_sync_ar
#: code:addons/account_online_sync_ar/models/account_online_provider.py:0
#, python-format
msgid ""
"406: Conflict - The institution does not allow to have more than one user "
"logged in. If you have logged in to your institution using another device, "
"please make sure to log out before trying again."
msgstr ""

#. module: account_online_sync_ar
#: code:addons/account_online_sync_ar/models/account_online_provider.py:0
#, python-format
msgid ""
"408: UserAction - The institution requires attention from the user. We "
"advise you to log in to the institution to confirm everything is working "
"properly. Upon confirmation, try again."
msgstr ""

#. module: account_online_sync_ar
#: code:addons/account_online_sync_ar/models/account_online_provider.py:0
#, python-format
msgid ""
"409: WrongSite - The given credentials seem to be valid but they belong to a"
" different site from the same organization."
msgstr ""

#. module: account_online_sync_ar
#: code:addons/account_online_sync_ar/models/account_online_provider.py:0
#, python-format
msgid "410: Waiting - Waiting for MFA Value"
msgstr ""

#. module: account_online_sync_ar
#: code:addons/account_online_sync_ar/models/account_online_provider.py:0
#, python-format
msgid ""
"411: TwofaTimeout - The time to introduce the MFA value has been exceeded."
msgstr ""

#. module: account_online_sync_ar
#: code:addons/account_online_sync_ar/models/account_online_provider.py:0
#, python-format
msgid "413: LoginError - There is a error in Login Process, please try again."
msgstr ""

#. module: account_online_sync_ar
#: code:addons/account_online_sync_ar/models/account_online_provider.py:0
#, python-format
msgid "429: Too Many Requests."
msgstr ""

#. module: account_online_sync_ar
#: code:addons/account_online_sync_ar/models/account_online_provider.py:0
#, python-format
msgid ""
"500: Error - An internal error has been ocurred while connecting to the "
"institution"
msgstr ""

#. module: account_online_sync_ar
#: code:addons/account_online_sync_ar/models/account_online_provider.py:0
#, python-format
msgid ""
"501: Unavailable - The instituion has informed to us that there was a "
"problem in the connection"
msgstr ""

#. module: account_online_sync_ar
#: code:addons/account_online_sync_ar/models/account_online_provider.py:0
#, python-format
msgid "503: Service Unavailable."
msgstr ""

#. module: account_online_sync_ar
#: code:addons/account_online_sync_ar/models/account_online_provider.py:0
#, python-format
msgid ""
"504: ConnectionTimeout - An internal error has been ocurred while connecting"
" to the institution."
msgstr ""

#. module: account_online_sync_ar
#: code:addons/account_online_sync_ar/models/account_online_provider.py:0
#, python-format
msgid "509: UndergoingMaintenance - The institution is under maintenance."
msgstr ""

#. module: account_online_sync_ar
#: model_terms:ir.ui.view,arch_db:account_online_sync_ar.update_credential
msgid "Actualizar Credencial del Banco"
msgstr ""

#. module: account_online_sync_ar
#: model_terms:ir.ui.view,arch_db:account_online_sync_ar.online_provider_account_form_view
msgid "Add/Configure accounts"
msgstr ""

#. module: account_online_sync_ar
#: code:addons/account_online_sync_ar/models/account_online_provider.py:0
#, python-format
msgid "An error has occurred (code %s)"
msgstr ""

#. module: account_online_sync_ar
#: code:addons/account_online_sync_ar/models/account_online_provider.py:0
#, python-format
msgid "Bad Request."
msgstr ""

#. module: account_online_sync_ar
#: model_terms:ir.ui.view,arch_db:account_online_sync_ar.online_provider_account_form_view
msgid "Check Status"
msgstr ""

#. module: account_online_sync_ar
#: model:ir.model,name:account_online_sync_ar.model_res_company
msgid "Companies"
msgstr ""

#. module: account_online_sync_ar
#: model_terms:ir.ui.view,arch_db:account_online_sync_ar.paybook_login
#: model_terms:ir.ui.view,arch_db:account_online_sync_ar.update_credential
msgid "Company ID"
msgstr ""

#. module: account_online_sync_ar
#: code:addons/account_online_sync_ar/models/account_online_provider.py:0
#, python-format
msgid ""
"Conflict - The institution does not allow to have more than one user logged "
"in. If you have logged in to your institution using another device, please "
"make sure to log out before trying again."
msgstr ""

#. module: account_online_sync_ar
#: code:addons/account_online_sync_ar/models/account_online_provider.py:0
#, python-format
msgid ""
"ConnectionTimeout - An internal error has been ocurred while connecting to "
"the institution."
msgstr ""

#. module: account_online_sync_ar
#: model_terms:ir.ui.view,arch_db:account_online_sync_ar.paybook_login
#: model_terms:ir.ui.view,arch_db:account_online_sync_ar.update_credential
msgid "Credential ID"
msgstr ""

#. module: account_online_sync_ar
#: model_terms:ir.ui.view,arch_db:account_online_sync_ar.online_provider_account_form_view
msgid "Delete Online Credentials"
msgstr ""

#. module: account_online_sync_ar
#: code:addons/account_online_sync_ar/models/account_online_provider.py:0
#, python-format
msgid ""
"Error - An internal error has been ocurred while connecting to the "
"institution"
msgstr ""

#. module: account_online_sync_ar
#: code:addons/account_online_sync_ar/models/res_company.py:0
#, python-format
msgid ""
"Falta configuración de credenciales de ADHOC para consulta del user token"
msgstr ""

#. module: account_online_sync_ar
#: code:addons/account_online_sync_ar/models/res_company.py:0
#, python-format
msgid "Falta configuración de credenciales de ADHOC para creacion de new user"
msgstr ""

#. module: account_online_sync_ar
#: code:addons/account_online_sync_ar/models/account_online_provider.py:0
#, python-format
msgid "Finish - The connection has been successful. Data has been extracted"
msgstr ""

#. module: account_online_sync_ar
#: code:addons/account_online_sync_ar/models/account_online_provider.py:0
#, python-format
msgid ""
"Forbidden or Invalidtoken - The given token value introduced was not "
"accepted by the institution or the expiration time was reached."
msgstr ""

#. module: account_online_sync_ar
#: model_terms:ir.ui.view,arch_db:account_online_sync_ar.online_provider_account_form_view
msgid "Force Sync"
msgstr ""

#. module: account_online_sync_ar
#: model_terms:ir.ui.view,arch_db:account_online_sync_ar.update_credential
msgid "ID Site"
msgstr ""

#. module: account_online_sync_ar
#: code:addons/account_online_sync_ar/models/account_online_provider.py:0
#, python-format
msgid ""
"Incomplete - The connection has been successful. However, the data "
"downloaded is incompleted."
msgstr ""

#. module: account_online_sync_ar
#: model:ir.model,name:account_online_sync_ar.model_account_online_journal
msgid "Interface for Online Account Journal"
msgstr ""

#. module: account_online_sync_ar
#: model:ir.model,name:account_online_sync_ar.model_account_journal
msgid "Journal"
msgstr ""

#. module: account_online_sync_ar
#: model_terms:ir.ui.view,arch_db:account_online_sync_ar.paybook_login
#: model_terms:ir.ui.view,arch_db:account_online_sync_ar.update_credential
msgid "Journal ID"
msgstr ""

#. module: account_online_sync_ar
#: model:ir.model.fields,field_description:account_online_sync_ar.field_account_bank_statement_import_journal_creation__paybook_last_transaction
#: model:ir.model.fields,field_description:account_online_sync_ar.field_account_journal__paybook_last_transaction
msgid "Last synced transaction"
msgstr ""

#. module: account_online_sync_ar
#: model_terms:ir.ui.view,arch_db:account_online_sync_ar.account_journal_dashboard_inherit_online_sync
msgid "Last:"
msgstr ""

#. module: account_online_sync_ar
#: code:addons/account_online_sync_ar/models/account_online_provider.py:0
#, python-format
msgid ""
"Locked - The institution has blocked the given credential, please contact "
"your institution and make sure your connection to the site is working "
"properly before trying again."
msgstr ""

#. module: account_online_sync_ar
#: code:addons/account_online_sync_ar/models/account_online_provider.py:0
#, python-format
msgid "LoginError - There is a error in Login Process, please try again."
msgstr ""

#. module: account_online_sync_ar
#: model:ir.model.fields,field_description:account_online_sync_ar.field_account_bank_statement_import_journal_creation__paybook_next_available
#: model:ir.model.fields,field_description:account_online_sync_ar.field_account_journal__paybook_next_available
#: model:ir.model.fields,field_description:account_online_sync_ar.field_account_online_provider__paybook_next_refresh
msgid "Next transactions will be available at"
msgstr ""

#. module: account_online_sync_ar
#: model_terms:ir.ui.view,arch_db:account_online_sync_ar.account_journal_dashboard_inherit_online_sync
msgid "Next:"
msgstr ""

#. module: account_online_sync_ar
#: code:addons/account_online_sync_ar/models/account_online_provider.py:0
#, python-format
msgid ""
"NoAccounts - The connection has been successful. However, there were no "
"accounts linked to the given credentials."
msgstr ""

#. module: account_online_sync_ar
#: code:addons/account_online_sync_ar/models/account_online_provider.py:0
#, python-format
msgid ""
"NoTransactions - The connection has been successful. However, no "
"transactions were found."
msgstr ""

#. module: account_online_sync_ar
#: code:addons/account_online_sync_ar/models/account_online_provider.py:0
#, python-format
msgid "Not Found."
msgstr ""

#. module: account_online_sync_ar
#: model:ir.model.fields,field_description:account_online_sync_ar.field_account_online_provider__next_refresh
msgid "Odoo cron next run"
msgstr ""

#. module: account_online_sync_ar
#: code:addons/account_online_sync_ar/models/account_online_provider.py:0
#, python-format
msgid ""
"PartialTransactions - The connection has been successful. However, more than"
" one account does not have transactions."
msgstr ""

#. module: account_online_sync_ar
#: code:addons/account_online_sync_ar/models/account_online_provider.py:0
#: model:ir.model.fields.selection,name:account_online_sync_ar.selection__account_online_provider__provider_type__paybook
#, python-format
msgid "Paybook"
msgstr ""

#. module: account_online_sync_ar
#: model_terms:ir.ui.view,arch_db:account_online_sync_ar.paybook_login
msgid "Paybook Odoo"
msgstr ""

#. module: account_online_sync_ar
#: model:ir.model.fields,field_description:account_online_sync_ar.field_res_company__paybook_user_id
msgid "Paybook User ID"
msgstr ""

#. module: account_online_sync_ar
#: model_terms:ir.ui.view,arch_db:account_online_sync_ar.paybook_login
#: model_terms:ir.ui.view,arch_db:account_online_sync_ar.update_credential
msgid "Paybook User Token"
msgstr ""

#. module: account_online_sync_ar
#: code:addons/account_online_sync_ar/models/account_online_provider.py:0
#: code:addons/account_online_sync_ar/models/account_online_provider.py:0
#, python-format
msgid ""
"Paybook fetch: Please comunicate with your Odoo Provider. This is what we "
"got %s"
msgstr ""

#. module: account_online_sync_ar
#: code:addons/account_online_sync_ar/models/account_online_provider.py:0
#, python-format
msgid "Payment Required"
msgstr ""

#. module: account_online_sync_ar
#: code:addons/account_online_sync_ar/models/account_online_provider.py:0
#, python-format
msgid ""
"Pending - The connection has been successful. We have partially extracted "
"information but data will still be extracted in background processes."
msgstr ""

#. module: account_online_sync_ar
#: model:ir.model.fields,field_description:account_online_sync_ar.field_account_bank_statement_import_journal_creation__account_online_provider_type
#: model:ir.model.fields,field_description:account_online_sync_ar.field_account_journal__account_online_provider_type
#: model:ir.model.fields,field_description:account_online_sync_ar.field_account_online_provider__provider_type
msgid "Provider Type"
msgstr ""

#. module: account_online_sync_ar
#: model:ir.model,name:account_online_sync_ar.model_account_online_provider
msgid "Provider for online account synchronization"
msgstr ""

#. module: account_online_sync_ar
#: code:addons/account_online_sync_ar/models/account_online_provider.py:0
#, python-format
msgid "Register - The API registers a new process (through a REST request)"
msgstr ""

#. module: account_online_sync_ar
#: code:addons/account_online_sync_ar/models/account_online_provider.py:0
#, python-format
msgid "Running - The process is running (login successful)"
msgstr ""

#. module: account_online_sync_ar
#: code:addons/account_online_sync_ar/models/account_online_provider.py:0
#: code:addons/account_online_sync_ar/models/account_online_provider.py:0
#, python-format
msgid "Server not reachable, please try again later"
msgstr ""

#. module: account_online_sync_ar
#: code:addons/account_online_sync_ar/models/account_online_provider.py:0
#, python-format
msgid "Service Unavailable."
msgstr ""

#. module: account_online_sync_ar
#: code:addons/account_online_sync_ar/models/account_online_provider.py:0
#, python-format
msgid "Starting - The process information was obtained to start operating"
msgstr ""

#. module: account_online_sync_ar
#: model_terms:ir.ui.view,arch_db:account_online_sync_ar.update_credential
msgid "State"
msgstr ""

#. module: account_online_sync_ar
#: model_terms:ir.ui.view,arch_db:account_online_sync_ar.paybook_login
#: model_terms:ir.ui.view,arch_db:account_online_sync_ar.update_credential
msgid "Test it"
msgstr ""

#. module: account_online_sync_ar
#: code:addons/account_online_sync_ar/models/account_online_provider.py:0
#: code:addons/account_online_sync_ar/models/account_online_provider.py:0
#, python-format
msgid "The next transactions sync will be available in %s hours"
msgstr ""

#. module: account_online_sync_ar
#: code:addons/account_online_sync_ar/models/account_online_provider.py:0
#, python-format
msgid "There is not account credential to be deleted"
msgstr ""

#. module: account_online_sync_ar
#: model_terms:ir.ui.view,arch_db:account_online_sync_ar.online_provider_account_form_view
msgid ""
"This action can not be undone. Are you sure? This can affect any other "
"database using the same credential"
msgstr ""

#. module: account_online_sync_ar
#: code:addons/account_online_sync_ar/models/account_online_provider.py:0
#: code:addons/account_online_sync_ar/models/account_online_provider.py:0
#, python-format
msgid "Timeout: the server did not reply within 60s"
msgstr ""

#. module: account_online_sync_ar
#: code:addons/account_online_sync_ar/models/account_online_provider.py:0
#, python-format
msgid "TokenReceived - The process received the token"
msgstr ""

#. module: account_online_sync_ar
#: code:addons/account_online_sync_ar/models/account_online_provider.py:0
#, python-format
msgid "Too Many Requests."
msgstr ""

#. module: account_online_sync_ar
#: code:addons/account_online_sync_ar/models/account_online_provider.py:0
#, python-format
msgid "TwofaTimeout - The time to introduce the MFA value has been exceeded."
msgstr ""

#. module: account_online_sync_ar
#: code:addons/account_online_sync_ar/models/account_online_provider.py:0
#, python-format
msgid ""
"Unauthorized - The value of one of the given Authentication Fields was not "
"accepted by the institution. Please verify the information and try again."
msgstr ""

#. module: account_online_sync_ar
#: code:addons/account_online_sync_ar/models/account_online_provider.py:0
#, python-format
msgid ""
"Unavailable - The instituion has informed to us that there was a problem in "
"the connection. Please wait 15 minutes and try again. If the problem "
"persists contact Technical Support."
msgstr ""

#. module: account_online_sync_ar
#: code:addons/account_online_sync_ar/models/account_online_provider.py:0
#, python-format
msgid "UndergoingMaintenance - The institution is under maintenance."
msgstr ""

#. module: account_online_sync_ar
#: code:addons/account_online_sync_ar/models/account_online_provider.py:0
#: code:addons/account_online_sync_ar/models/account_online_provider.py:0
#, python-format
msgid "Unknown exception %s"
msgstr ""

#. module: account_online_sync_ar
#: model_terms:ir.ui.view,arch_db:account_online_sync_ar.online_provider_account_form_view
msgid "Update Password"
msgstr ""

#. module: account_online_sync_ar
#: code:addons/account_online_sync_ar/models/account_online_provider.py:0
#, python-format
msgid ""
"UserAction - The institution requires attention from the user. We advise you"
" to log in to the institution to confirm everything is working properly. "
"Upon confirmation, try again."
msgstr ""

#. module: account_online_sync_ar
#: code:addons/account_online_sync_ar/models/account_online_provider.py:0
#, python-format
msgid "Waiting - Waiting for MFA Value"
msgstr ""

#. module: account_online_sync_ar
#: model_terms:ir.ui.view,arch_db:account_online_sync_ar.update_credential
msgid "Widget Res"
msgstr ""

#. module: account_online_sync_ar
#: code:addons/account_online_sync_ar/models/account_online_provider.py:0
#, python-format
msgid ""
"WrongSite - The given credentials seem to be valid but they belong to a "
"different site from the same organization."
msgstr ""

#. module: account_online_sync_ar
#: code:addons/account_online_sync_ar/models/account_online_provider.py:0
#, python-format
msgid "We don't find any new account to add / configure"
msgstr ""
